{"timestamp": "2025-08-01 23:12:51,190", "level": "ERROR", "module": "auth_services", "message": "Error al validar el usuario Mendo1029: (pymysql.err.OperationalError) (2003, \"Can't connect to MySQL server on 'db' ([Errno 11001] getaddrinfo failed)\")\n(Background on this error at: https://sqlalche.me/e/20/e3q8)", "ip": "10.2.0.2"}
{"timestamp": "2025-08-01 23:14:11,065", "level": "ERROR", "module": "auth_services", "message": "Error al validar el usuario Mendo1029: (pymysql.err.OperationalError) (2003, \"Can't connect to MySQL server on 'db' ([Errno 11002] getaddrinfo failed)\")\n(Background on this error at: https://sqlalche.me/e/20/e3q8)", "ip": "10.2.0.2"}
{"timestamp": "2025-08-01 23:16:51,710", "level": "ERROR", "module": "auth_services", "message": "Error al validar el usuario Mendo1029: (pymysql.err.OperationalError) (2003, \"Can't connect to MySQL server on 'db' ([Errno 11002] getaddrinfo failed)\")\n(Background on this error at: https://sqlalche.me/e/20/e3q8)", "ip": "10.2.0.2"}
{"timestamp": "2025-08-01 23:19:26,372", "level": "INFO", "module": "auth_services", "message": "Usuario autenticado exitosamente: Mendo1029", "ip": "10.2.0.2"}
{"timestamp": "2025-08-01 23:19:27,014", "level": "INFO", "module": "task_service", "message": "Obtenidas 5 tareas ", "ip": "10.2.0.2"}
